Workbook

Sheet Sheet2
A3: Type | B3: Count of Type
A4: Length Mismatch | B4: 21
A5: Similarity Score Issue | B5: 6
A6: Success | B6: 20
A7: Syntax Error | B7: 10

Sheet Sheet3
A3: Row Labels | B3: Count of Details
A4: Length Mismatch | B4: 21
A5: Target1_13 | B5: 1
A6: Target1_18 | B6: 1
A7: Target1_22 | B7: 1
A8: Target1_24 | B8: 1
A9: Target1_27 | B9: 1
A10: Target1_41 | B10: 1
A11: Target1_43 | B11: 1
A12: Target1_46 | B12: 1
A13: Target1_48 | B13: 1
A14: Target1_52 | B14: 1
A15: Target1_53 | B15: 1
... A27: Target1_10 | B27: 1
A28: Target1_16
A29: Target1_23 | B29: 1
A30: Target1_62 | B30: 1
A31: Target1_86 | B31: 1
A32: Target1_97 | B32: 1
A33: Success | B33: 20
A34: Syntax Error | B34: 10
A35: Target1_40 | B35: 1
A36: Target1_44 | B36: 1
A37: Target1_59 | B37: 1
A38: Target1_78 | B38: 1
A39: Target1_88 | B39: 1
A40: Target1_89 | B40: 1
... A44: Target1_93 | B44: 1
A45: (blank)
A46: (blank)
A47: Grand Total | B47: 56

Sheet Sheet4
A3: Row Labels | B3: Count of After Fix
A4: Bad Case - task makes no sense | B4: 2
A5: Failed - did not figured out | B5: 1
A6: Failed - failed to aggregate - low entropy - data type change | B6: 2
A7: Failed - failed to aggregate - low entropy - domain knowledge | B7: 10
A8: Failed - failed to aggregate - low entropy - domain knowledge - hard (newest date) | B8: 1
A9: Failed - failed to aggregate - low entropy - domain knowledge/ did not do count | B9: 1
A10: Need Domain Knowledge - Aggregation function | B10: 2
A11: Need Domain Knowledge - Aggregation target | B11: 1
A12: Need Domain Knowledge - expectation/ count on which | B12: 1
A13: Need Domain Knowledge - Rare case/ expectation | B13: 1
A14: Need Domain Knowledge - Use Aggregation or not | B14: 1
A15: Success | B15: 26
... A20: Success* bad test case : Dec_2012 vs Dec_2013 | B20: 2
A21: (blank)
A22: Grand Total | B22: 57
A29: Bad Case - task makes no sense | B29: 2
A30: Failed - did not figured out | B30: 1 | E30: 1
A31: Failed - failed to aggregate - low entropy - data type change | B31: 2 | E31: 2
A32: Failed - failed to aggregate - low entropy - domain knowledge | B32: 10 | E32: 10
A33: Failed - failed to aggregate - low entropy - domain knowledge - hard (newest date) | B33: 1 | E33: 1
A34: Failed - failed to aggregate - low entropy - domain knowledge/ did not do count | B34: 1 | E34: 1
A35: Need Domain Knowledge - Aggregation function | B35: 2 | E35: 2 | H35: before fix 20/57 | I35: =20/57 -> 0.35087719
A36: Need Domain Knowledge - Aggregation target | B36: 1 | E36: 1
A37: Need Domain Knowledge - expectation/ count on which | B37: 1 | E37: 1
A38: Need Domain Knowledge - Rare case/ expectation | B38: 1 | E38: 1 | H38: Bad Case - task makes no sense | I38: 2
A39: Need Domain Knowledge - Use Aggregation or not | B39: 1 | E39: 1 | H39: Domain Knolwedge needed/ likely to be success when Domain Knoledge is provided | I39: =SUM(E30:E39) -> 21
A40: Success | B40: 26 | D40: 26 | H40: Success | I40: =SUM(D40:D45) -> 34
A41: Success - next iteration | B41: 3 | D41: 3
A42: Success* grouped by continent - did not remove the empty conservation_status - I would not call this failed.. | B42: 1 | D42: 1 | H42: 34/(21+34） | I42: =34/ (34+21) -> 0.61818182
A43: Success* grouped by continent - did not remove the empty continent - I would not call this failed.. | B43: 1 | D43: 1
A44: Success* grouped by continent - did not remove the empty fac_type - I would not call this failed.. | B44: 1 | D44: 1
A45: Success* bad test case : Dec_2012 vs Dec_2013 | B45: 2 | D45: 2

Sheet Sheet6
A3: Row Labels | B3: Count of overall_big_prompt_no_fewshot_no_detailed intruction
A4: Bad Case - task makes no sense v.s. Failed | B4: 2
A5: Target1_44 | B5: 1
A6: Target1_89 | B6: 1
A7: Failed - did not figured out v.s. Failed | B7: 1
A8: Target1_99 | B8: 1
A9: Failed - failed to aggregate - low entropy - data type change v.s. Failed | B9: 2
A10: Target1_43 | B10: 1
A11: Target1_52 | B11: 1
A12: Failed - failed to aggregate - low entropy - domain knowledge - hard (newest date) v.s. Failed | B12: 1
A13: Target1_95 | B13: 1
A14: Failed - failed to aggregate - low entropy - domain knowledge v.s. Failed | B14: 8
A15: Target1_18 | B15: 1
... A35: Target1_97 | B35: 1
A36: Need Domain Knowledge - Rare case/ expectation v.s. Failed | B36: 1 | E36: 1 | H36: one-big-prompt | I36: =32/(21+34) -> 0.58181818
A37: Target1_90 | B37: 1 | E37: 1 | H37: react | I37: =34/(21+34) -> 0.61818182
A38: Need Domain Knowledge - Use Aggregation or not v.s. Failed | B38: 1 | E38: 6
A39: Target1_78 | B39: 1 | E39: 1
A40: Success - next iteration v.s. Failed | B40: 1
A41: Target1_93 | B41: 1
A42: Success - next iteration v.s. Success | B42: 2
A43: Target1_10 | B43: 1
A44: Target1_92 | B44: 1 | D44: success -> failed | E44: 4 | F44: 2 | G44: failed -> success
A45: Success v.s. Failed | B45: 3 | E45: Target1_72 | F45: Target1_61
A46: Target1_72 | B46: 1 | E46: Target1_84 | F46: Target1_97
A47: Target1_84 | B47: 1 | E47: Target1_88
A48: Target1_88 | B48: 1 | E48: Target1_93
A49: Success v.s. Failed - DID NOT DO SUBSTRING --> Success | B49: 1
A50: Target1_68 | B50: 1
A51: Success v.s. Failed --> Success | B51: 5
A52: Target1_34 | B52: 1
A53: Target1_35 | B53: 1
A54: Target1_38 | B54: 1
A55: Target1_6 | B55: 1
A56: Target1_80 | B56: 1
A57: Success v.s. Failed* VERY CLOSE.. CHECK | B57: 1 | I57: Target1_6
A58: Target1_55 | B58: 1 | I58: Target1_35
A59: Success v.s. Success | B59: 11 | I59: Target1_40
A60: Target1_11 | B60: 1 | I60: Target1_57
A61: Target1_20 | B61: 1 | I61: Target1_91
...

Sheet Sheet1
A1: Target | B1: Success Once | C1: React - After Fix | D1: Ankita's baseline without target samples | E1: Ankita's baseline with target samples | F1: one_big_prompt | G1: one_big_prompt_5itrs | H1: overall_big_prompt_no_fewshot_no_detailed intruction | J1: Type | K1: Details
A2: Target1_3 | B2: Success | C2: Success | D2: =VLOOKUP(Sheet1!A2,Sheet5!B$1:AA$613,26,FALSE) -> 0 | E2: =VLOOKUP(Sheet1!A2,Sheet5!B$1:AA$613,25,FALSE) -> success | F2: Success | G2: Success | H2: =C2 & " v.s. " & IF(AND(NOT(ISBLANK(F2)), NOT(ISBLANK(G2))), F2 & " --> " & G2, F2 & G2) -> Success v.s. Success --> Success | J2: Success | K2: Execution successful without errors.
A3: Target1_4 | B3: Success | C3: Success | D3: =VLOOKUP(Sheet1!A3,Sheet5!B$1:AA$613,26,FALSE) -> success | E3: =VLOOKUP(Sheet1!A3,Sheet5!B$1:AA$613,25,FALSE) -> success | F3: Success | G3: Success | H3: =C3 & " v.s. " & IF(AND(NOT(ISBLANK(F3)), NOT(ISBLANK(G3))), F3 & " --> " & G3, F3 & G3) -> Success v.s. Success --> Success | J3: Success | K3: Execution successful without errors.
A4: Target1_6 | B4: Success | C4: Success | D4: =VLOOKUP(Sheet1!A4,Sheet5!B$1:AA$613,26,FALSE) -> failed | E4: =VLOOKUP(Sheet1!A4,Sheet5!B$1:AA$613,25,FALSE) -> failed | F4: Failed | G4: Success | H4: =C4 & " v.s. " & IF(AND(NOT(ISBLANK(F4)), NOT(ISBLANK(G4))), F4 & " --> " & G4, F4 & G4) -> Success v.s. Failed --> Success | I4: ['Mismatch - DataFrames lengths differ (100000 vs 3164)'] | J4: Success | K4: Execution successful without errors.
A5: Target1_9 | B5: Failed | C5: Need Domain Knowledge - Aggregation target | D5: =VLOOKUP(Sheet1!A5,Sheet5!B$1:AA$613,26,FALSE) -> #N/A | E5: =VLOOKUP(Sheet1!A5,Sheet5!B$1:AA$613,25,FALSE) -> #N/A | F5: Failed | G5: Need Domain Knowledge | H5: =C5 & " v.s. " & IF(AND(NOT(ISBLANK(F5)), NOT(ISBLANK(G5))), F5 & " --> " & G5, F5 & G5) -> Need Domain Knowledge - Aggregation target v.s. Failed --> Need Domain Knowledge | I5: Error in the previous response: Error: ERROR: syntax error at or near ")" LINE 20: ); ^ | J5: Length Mismatch | K5: Mismatch - Lists lengths differ'
A6: Target1_10 | B6: Failed | C6: Success - next iteration | D6: =VLOOKUP(Sheet1!A6,Sheet5!B$1:AA$613,26,FALSE) -> failed | E6: =VLOOKUP(Sheet1!A6,Sheet5!B$1:AA$613,25,FALSE) -> succes | F6: Success | G6: Success | H6: =C6 & " v.s. " & IF(AND(NOT(ISBLANK(F6)), NOT(ISBLANK(G6))), F6 & " --> " & G6, F6 & G6) -> Success - next iteration v.s. Success --> Success | J6: Similarity Score Issue | K6: Scores: 1.0, 0.9982; Case accuracy: 1.00 | L6: ['Column 2: None vs 0']
A7: Target1_11 | B7: Success | C7: Success | D7: =VLOOKUP(Sheet1!A7,Sheet5!B$1:AA$613,26,FALSE) -> failed | E7: =VLOOKUP(Sheet1!A7,Sheet5!B$1:AA$613,25,FALSE) -> failed | F7: Success | G7: Success | H7: =C7 & " v.s. " & IF(AND(NOT(ISBLANK(F7)), NOT(ISBLANK(G7))), F7 & " --> " & G7, F7 & G7) -> Success v.s. Success --> Success | J7: Success | K7: Execution successful without errors.
A8: Target1_13 | B8: Failed | C8: Failed - failed to aggregate - low entropy - domain knowledge | D8: =VLOOKUP(Sheet1!A8,Sheet5!B$1:AA$613,26,FALSE) -> failed | E8: =VLOOKUP(Sheet1!A8,Sheet5!B$1:AA$613,25,FALSE) -> failed | F8: Failed | G8: Need Domain Knowledge | H8: =C8 & " v.s. " & IF(AND(NOT(ISBLANK(F8)), NOT(ISBLANK(G8))), F8 & " --> " & G8, F8 & G8) -> Failed - failed to aggregate - low entropy - domain knowledge v.s. Failed --> Need Domain Knowledge | I8: ['Mismatch - DataFrames lengths differ (122 vs 4)'] | J8: Length Mismatch | K8: Mismatch - Lists lengths differ'
A9: Target1_16 | B9: Failed | C9: Success - preprocessing | D9: =VLOOKUP(Sheet1!A9,Sheet5!B$1:AA$613,26,FALSE) -> failed | E9: =VLOOKUP(Sheet1!A9,Sheet5!B$1:AA$613,25,FALSE) -> Still failed even after clean.py pre processing | F9: Failed - syntax | G9: Success | H9: =C9 & " v.s. " & IF(AND(NOT(ISBLANK(F9)), NOT(ISBLANK(G9))), F9 & " --> " & G9, F9 & G9) -> Success - preprocessing v.s. Failed - syntax --> Success | I9: Error in the previous response: Error: ERROR: invalid input syntax for type integer: "ORDERNUMBER" CONTEXT: COPY Source1_16_0, line 1, column ORDERNUMBER: "ORDERNUMBER" | J9: Similarity Score Issue
A10: Target1_18 | B10: Failed | C10: Failed - failed to aggregate - low entropy - domain knowledge | D10: =VLOOKUP(Sheet1!A10,Sheet5!B$1:AA$613,26,FALSE) -> failed | E10: =VLOOKUP(Sheet1!A10,Sheet5!B$1:AA$613,25,FALSE) -> failed | F10: Failed | G10: Need Domain Knowledge | H10: =C10 & " v.s. " & IF(AND(NOT(ISBLANK(F10)), NOT(ISBLANK(G10))), F10 & " --> " & G10, F10 & G10) -> Failed - failed to aggregate - low entropy - domain knowledge v.s. Failed --> Need Domain Knowledge | I10: ['Mismatch - DataFrames lengths differ (75 vs 2)'] | J10: Length Mismatch | K10: Mismatch - Lists lengths differ'
A11: Target1_20 | B11: Success | C11: Success | D11: =VLOOKUP(Sheet1!A11,Sheet5!B$1:AA$613,26,FALSE) -> failed | E11: =VLOOKUP(Sheet1!A11,Sheet5!B$1:AA$613,25,FALSE) -> failed | F11: Success | G11: Success | H11: =C11 & " v.s. " & IF(AND(NOT(ISBLANK(F11)), NOT(ISBLANK(G11))), F11 & " --> " & G11, F11 & G11) -> Success v.s. Success --> Success | J11: Success | K11: Execution successful without errors.
A12: Target1_21 | B12: Success | C12: Success | D12: =VLOOKUP(Sheet1!A12,Sheet5!B$1:AA$613,26,FALSE) -> failed | E12: =VLOOKUP(Sheet1!A12,Sheet5!B$1:AA$613,25,FALSE) -> success | F12: Success | G12: Success | H12: =C12 & " v.s. " & IF(AND(NOT(ISBLANK(F12)), NOT(ISBLANK(G12))), F12 & " --> " & G12, F12 & G12) -> Success v.s. Success --> Success | J12: Success | K12: Execution successful without errors.
A13: Target1_22 | B13: Failed | C13: Failed - failed to aggregate - low entropy - domain knowledge | D13: =VLOOKUP(Sheet1!A13,Sheet5!B$1:AA$613,26,FALSE) -> failed | E13: =VLOOKUP(Sheet1!A13,Sheet5!B$1:AA$613,25,FALSE) -> failed | F13: Failed | G13: Need Domain Knowledge | H13: =C13 & " v.s. " & IF(AND(NOT(ISBLANK(F13)), NOT(ISBLANK(G13))), F13 & " --> " & G13, F13 & G13) -> Failed - failed to aggregate - low entropy - domain knowledge v.s. Failed --> Need Domain Knowledge | I13: ['Mismatch - DataFrames lengths differ (4 vs 2)'] | J13: Length Mismatch | K13: Mismatch - Lists lengths differ'
A14: Target1_23 | B14: Failed | C14: Need Domain Knowledge - Aggregation function | D14: =VLOOKUP(Sheet1!A14,Sheet5!B$1:AA$613,26,FALSE) -> failed | E14: =VLOOKUP(Sheet1!A14,Sheet5!B$1:AA$613,25,FALSE) -> failed | F14: Failed | G14: Need Domain Knowledge | H14: =C14 & " v.s. " & IF(AND(NOT(ISBLANK(F14)), NOT(ISBLANK(G14))), F14 & " --> " & G14, F14 & G14) -> Need Domain Knowledge - Aggregation function v.s. Failed --> Need Domain Knowledge | I14: Error in the previous response: Error: ERROR: invalid input syntax for type integer: "customer_id" CONTEXT: COPY Source1_23_0, line 1, column customer_id: "customer_id" | J14: Similarity Score Issue | K14: Scores: 1.0, 0.5758; Case accuracy: 0.79 | L14: too long to list, refer to 'revised_finish_1.log'
A15: Target1_24 | B15: Failed | C15: Failed - failed to aggregate - low entropy - domain knowledge | D15: =VLOOKUP(Sheet1!A15,Sheet5!B$1:AA$613,26,FALSE) -> #N/A | E15: =VLOOKUP(Sheet1!A15,Sheet5!B$1:AA$613,25,FALSE) -> #N/A | F15: Failed | G15: Need Domain Knowledge | H15: =C15 & " v.s. " & IF(AND(NOT(ISBLANK(F15)), NOT(ISBLANK(G15))), F15 & " --> " & G15, F15 & G15) -> Failed - failed to aggregate - low entropy - domain knowledge v.s. Failed --> Need Domain Knowledge | I15: Error in the previous response: Error: ERROR: cannot subscript type numeric because it does not support subscripting LINE 31: SELECT unnest[1]::DECIMAL AS "condition", unnest[2]::DECIMAL… | J15: Length Mismatch | K15: Mismatch - Lists lengths differ'
A16: Target1_27 | B16: Failed | C16: Failed - failed to aggregate - low entropy - domain knowledge | D16: =VLOOKUP(Sheet1!A16,Sheet5!B$1:AA$613,26,FALSE) -> failed | E16: =VLOOKUP(Sheet1!A16,Sheet5!B$1:AA$613,25,FALSE) -> failed | F16: Failed | G16: Need Domain Knowledge | H16: =C16 & " v.s. " & IF(AND(NOT(ISBLANK(F16)), NOT(ISBLANK(G16))), F16 & " --> " & G16, F16 & G16) -> Failed - failed to aggregate - low entropy - domain knowledge v.s. Failed --> Need Domain Knowledge | I16: ['Mismatch - DataFrames lengths differ (21324 vs 7)']. | J16: Length Mismatch | K16: Mismatch - Lists lengths differ'
A17: Target1_29 | B17: Success | C17: Success | D17: =VLOOKUP(Sheet1!A17,Sheet5!B$1:AA$613,26,FALSE) -> failed | E17: =VLOOKUP(Sheet1!A17,Sheet5!B$1:AA$613,25,FALSE) -> success | F17: Success | G17: Success | H17: =C17 & " v.s. " & IF(AND(NOT(ISBLANK(F17)), NOT(ISBLANK(G17))), F17 & " --> " & G17, F17 & G17) -> Success v.s. Success --> Success | J17: Success | K17: Execution successful without errors.
A18: Target1_34 | B18: Success | C18: Success | D18: =VLOOKUP(Sheet1!A18,Sheet5!B$1:AA$613,26,FALSE) -> success | E18: =VLOOKUP(Sheet1!A18,Sheet5!B$1:AA$613,25,FALSE) -> success | F18: Failed | G18: Success | H18: =C18 & " v.s. " & IF(AND(NOT(ISBLANK(F18)), NOT(ISBLANK(G18))), F18 & " --> " & G18, F18 & G18) -> Success v.s. Failed --> Success | I18: Error in the previous response: Error: ERROR: invalid input syntax for type json DETAIL: Token "J_CALL" is invalid. CONTEXT: JSON data, line 1: J_CALL COPY Source1_34_0, line 1, column J_CALL: "J_CALL" | J18: Success | K18: Malformed array literal 'IGHJ5*02'; Execution successful without errors. | L18: Error in the previous response: Error: ERROR: malformed array literal: "IGHJ5*02" DETAIL: Array value must start with "{" or dimension information. CONTEXT: COPY source1_34_0, line 2, column j_call: "IGHJ5*02"
A19: Target1_35 | B19: Success | C19: Success | D19: =VLOOKUP(Sheet1!A19,Sheet5!B$1:AA$613,26,FALSE) -> 0 | E19: =VLOOKUP(Sheet1!A19,Sheet5!B$1:AA$613,25,FALSE) -> failed | F19: Failed | G19: Success | H19: =C19 & " v.s. " & IF(AND(NOT(ISBLANK(F19)), NOT(ISBLANK(G19))), F19 & " --> " & G19, F19 & G19) -> Success v.s. Failed --> Success | I19: ['Mismatch - DataFrames lengths differ (367 vs 55)'] | J19: Success | K19: Mismatch - Lists lengths differ'; Execution successful without errors.
A20: Target1_38 | B20: Success | C20: Success | D20: =VLOOKUP(Sheet1!A20,Sheet5!B$1:AA$613,26,FALSE) -> 0 | E20: =VLOOKUP(Sheet1!A20,Sheet5!B$1:AA$613,25,FALSE) -> failed | F20: Failed | G20: Success | H20: =C20 & " v.s. " & IF(AND(NOT(ISBLANK(F20)), NOT(ISBLANK(G20))), F20 & " --> " & G20, F20 & G20) -> Success v.s. Failed --> Success | I20: iter1 Error in the previous response: Error: ERROR: invalid input syntax for type numeric: "user_id" CONTEXT: COPY Source1_38_0, line 1, column user_id: "user_id" | J20: Success | K20: Execution successful without errors.
A21: Target1_40 | B21: Failed | C21: Success - preprocessing | D21: =VLOOKUP(Sheet1!A21,Sheet5!B$1:AA$613,26,FALSE) -> data pre processing error | E21: =VLOOKUP(Sheet1!A21,Sheet5!B$1:AA$613,25,FALSE) -> 0 | F21: Failed | G21: Success - takes more itr? | H21: =C21 & " v.s. " & IF(AND(NOT(ISBLANK(F21)), NOT(ISBLANK(G21))), F21 & " --> " & G21, F21 & G21) -> Success - preprocessing v.s. Failed --> Success - takes more itr? | I21: ['Mismatch - DataFrames lengths differ (754 vs 153)'] | J21: Syntax Error | K21: Error in the previous response: Error: ERROR: invalid input syntax for type integer: "30.0" CONTEXT: COPY source1_40_0, line 2, column quantityordered: "30.0"
A22: Target1_41 | B22: Failed | C22: Failed - failed to aggregate - low entropy - domain knowledge | D22: =VLOOKUP(Sheet1!A22,Sheet5!B$1:AA$613,26,FALSE) -> failed | E22: =VLOOKUP(Sheet1!A22,Sheet5!B$1:AA$613,25,FALSE) -> failed | F22: Failed | G22: Need Domain Knowledge | H22: =C22 & " v.s. " & IF(AND(NOT(ISBLANK(F22)), NOT(ISBLANK(G22))), F22 & " --> " & G22, F22 & G22) -> Failed - failed to aggregate - low entropy - domain knowledge v.s. Failed --> Need Domain Knowledge | I22: ['Mismatch - DataFrames lengths differ (83156 vs 13861)'] | J22: Length Mismatch | K22: Mismatch - Lists lengths differ'
A23: Target1_43 | B23: Failed | C23: Failed - failed to aggregate - low entropy - data type change | D23: =VLOOKUP(Sheet1!A23,Sheet5!B$1:AA$613,26,FALSE) -> data pre processing error | E23: =VLOOKUP(Sheet1!A23,Sheet5!B$1:AA$613,25,FALSE) -> 0 | F23: Failed | G23: Need Domain Knowledge | H23: =C23 & " v.s. " & IF(AND(NOT(ISBLANK(F23)), NOT(ISBLANK(G23))), F23 & " --> " & G23, F23 & G23) -> Failed - failed to aggregate - low entropy - data type change v.s. Failed --> Need Domain Knowledge | I23: ['Mismatch - DataFrames lengths differ (322 vs 2)'] | J23: Length Mismatch | K23: Mismatch - Lists lengths differ'
A24: Target1_44 | B24: Failed | C24: Bad Case - task makes no sense | D24: =VLOOKUP(Sheet1!A24,Sheet5!B$1:AA$613,26,FALSE) -> data pre processing error | E24: =VLOOKUP(Sheet1!A24,Sheet5!B$1:AA$613,25,FALSE) -> 0 | F24: Failed | G24: Bad Case - task makes no sense | H24: =C24 & " v.s. " & IF(AND(NOT(ISBLANK(F24)), NOT(ISBLANK(G24))), F24 & " --> " & G24, F24 & G24) -> Bad Case - task makes no sense v.s. Failed --> Bad Case - task makes no sense | I24: iter1 Error in the previous response: Error: ERROR: invalid input syntax for type numeric: "*" CONTEXT: COPY Source1_44_0, line 26, column Value: "*" | J24: Syntax Error | K24: Error in the previous response: Error: ERROR: invalid input syntax for type numeric: "*" CONTEXT: COPY source1_44_0, line 26, column Value: "*"
A25: Target1_46 | B25: Failed | C25: Success* bad test case : Dec_2012 vs Dec_2013 | D25: =VLOOKUP(Sheet1!A25,Sheet5!B$1:AA$613,26,FALSE) -> 0 | E25: =VLOOKUP(Sheet1!A25,Sheet5!B$1:AA$613,25,FALSE) -> 0 | F25: Failed | G25: Success* bad test case : Dec_2012 vs Dec_2013 | H25: =C25 & " v.s. " & IF(AND(NOT(ISBLANK(F25)), NOT(ISBLANK(G25))), F25 & " --> " & G25, F25 & G25) -> Success* bad test case : Dec_2012 vs Dec_2013 v.s. Failed --> Success* bad test case : Dec_2012 vs Dec_2013 | I25: ['Mismatch - DataFrames lengths differ (6960 vs 96)'] | J25: Length Mismatch | K25: Mismatch - Lists lengths differ'
A26: Target1_48 | B26: Failed | C26: Success* bad test case : Dec_2012 vs Dec_2013 | D26: =VLOOKUP(Sheet1!A26,Sheet5!B$1:AA$613,26,FALSE) -> #N/A | E26: =VLOOKUP(Sheet1!A26,Sheet5!B$1:AA$613,25,FALSE) -> #N/A | F26: Success* | G26: Success | H26: =C26 & " v.s. " & IF(AND(NOT(ISBLANK(F26)), NOT(ISBLANK(G26))), F26 & " --> " & G26, F26 & G26) -> Success* bad test case : Dec_2012 vs Dec_2013 v.s. Success* --> Success | I26: [(0, [(23, 'Dec_2012', 'Dec_2013')])] | J26: Length Mismatch | K26: Mismatch - Lists lengths differ'
A27: Target1_52 | B27: Failed | C27: Failed - failed to aggregate - low entropy - data type change | D27: =VLOOKUP(Sheet1!A27,Sheet5!B$1:AA$613,26,FALSE) -> failed | E27: =VLOOKUP(Sheet1!A27,Sheet5!B$1:AA$613,25,FALSE) -> failed | F27: Failed | H27: =C27 & " v.s. " & IF(AND(NOT(ISBLANK(F27)), NOT(ISBLANK(G27))), F27 & " --> " & G27, F27 & G27) -> Failed - failed to aggregate - low entropy - data type change v.s. Failed | I27: Error: ERROR: malformed array literal: "1" DETAIL: Array value must start with "{" or dimension information. CONTEXT: COPY Source1_52_0, line 2, column condition: "1" | J27: Length Mismatch | K27: Mismatch - Lists lengths differ'
A28: Target1_53 | B28: Failed | C28: Success* grouped by continent - did not remove the empty continent - I would not call this failed.. | D28: =VLOOKUP(Sheet1!A28,Sheet5!B$1:AA$613,26,FALSE) -> failed | E28: =VLOOKUP(Sheet1!A28,Sheet5!B$1:AA$613,25,FALSE) -> failed | F28: Success* | G28: Success | H28: =C28 & " v.s. " & IF(AND(NOT(ISBLANK(F28)), NOT(ISBLANK(G28))), F28 & " --> " & G28, F28 & G28) -> Success* grouped by continent - did not remove the empty continent - I would not call this failed.. v.s. Success* --> Success | I28: ['Mismatch - DataFrames lengths differ (6 vs 5)'] | J28: Length Mismatch | K28: Mismatch - Lists lengths differ'
A29: Target1_54 | B29: Failed | C29: Failed - failed to aggregate - low entropy - domain knowledge | D29: =VLOOKUP(Sheet1!A29,Sheet5!B$1:AA$613,26,FALSE) -> #N/A | E29: =VLOOKUP(Sheet1!A29,Sheet5!B$1:AA$613,25,FALSE) -> #N/A | F29: Failed | G29: Need Domain Knowledge | H29: =C29 & " v.s. " & IF(AND(NOT(ISBLANK(F29)), NOT(ISBLANK(G29))), F29 & " --> " & G29, F29 & G29) -> Failed - failed to aggregate - low entropy - domain knowledge v.s. Failed --> Need Domain Knowledge | I29: Error: ERROR: malformed array literal: "1" DETAIL: Array value must start with "{" or dimension information. CONTEXT: COPY Source1_54_0, line 2, column condition: "1" | J29: Length Mismatch | K29: Mismatch - Lists lengths differ'
A30: Target1_55 | B30: Success | C30: Success | D30: =VLOOKUP(Sheet1!A30,Sheet5!B$1:AA$613,26,FALSE) -> #N/A | E30: =VLOOKUP(Sheet1!A30,Sheet5!B$1:AA$613,25,FALSE) -> #N/A | F30: Failed* VERY CLOSE.. CHECK | G30: Success | H30: =C30 & " v.s. " & IF(AND(NOT(ISBLANK(F30)), NOT(ISBLANK(G30))), F30 & " --> " & G30, F30 & G30) -> Success v.s. Failed* VERY CLOSE.. CHECK --> Success | I30: ['Mismatch - DataFrames lengths differ (6584 vs 6583)'] | J30: Success | K30: Execution successful without errors.
A31: Target1_57 | B31: Success | C31: Success | D31: =VLOOKUP(Sheet1!A31,Sheet5!B$1:AA$613,26,FALSE) -> 0 | E31: =VLOOKUP(Sheet1!A31,Sheet5!B$1:AA$613,25,FALSE) -> 0 | F31: Failed | G31: Success-itr2 | H31: =C31 & " v.s. " & IF(AND(NOT(ISBLANK(F31)), NOT(ISBLANK(G31))), F31 & " --> " & G31, F31 & G31) -> Success v.s. Failed --> Success-itr2 | I31: Error in the previous response: Error: ERROR: invalid input syntax for type numeric: "userId" CONTEXT: COPY Source1_57_0, line 1, column userId: "userId" | J31: Success | K31: Syntax error at or near "Finish"; Execution successful without errors.
A32: Target1_59 | B32: Failed | C32: Success - preprocessing | D32: =VLOOKUP(Sheet1!A32,Sheet5!B$1:AA$613,26,FALSE) -> ERROR: Error: ERROR: invalid input syntax for type integer: "2003.0" CONTEXT: COPY source59_0, line 2, column year_id: "2003.0" | E32: =VLOOKUP(Sheet1!A32,Sheet5!B$1:AA$613,25,FALSE) -> 0.5 success [1,0.7] score. | F32: Success | G32: Success | H32: =C32 & " v.s. " & IF(AND(NOT(ISBLANK(F32)), NOT(ISBLANK(G32))), F32 & " --> " & G32, F32 & G32) -> Success - preprocessing v.s. Success --> Success | J32: Syntax Error | K32: Error in the previous response: Error: ERROR: invalid input syntax for type integer: "2.0" CONTEXT: COPY source1_59_0, line 2, column orderlinenumber: "2.0"
A33: Target1_60 | B33: Success | C33: Success | D33: =VLOOKUP(Sheet1!A33,Sheet5!B$1:AA$613,26,FALSE) -> failed | E33: =VLOOKUP(Sheet1!A33,Sheet5!B$1:AA$613,25,FALSE) -> success | F33: Success | G33: Success | H33: =C33 & " v.s. " & IF(AND(NOT(ISBLANK(F33)), NOT(ISBLANK(G33))), F33 & " --> " & G33, F33 & G33) -> Success v.s. Success --> Success | J33: Success | K33: Execution successful without errors.
A34: Target1_61 | B34: Failed | C34: Failed - failed to aggregate - low entropy - domain knowledge | D34: =VLOOKUP(Sheet1!A34,Sheet5!B$1:AA$613,26,FALSE) -> #N/A | E34: =VLOOKUP(Sheet1!A34,Sheet5!B$1:AA$613,25,FALSE) -> #N/A | F34: Success** DID BETTER!!! BY CHANCE I GUESS.. | H34: =C34 & " v.s. " & IF(AND(NOT(ISBLANK(F34)), NOT(ISBLANK(G34))), F34 & " --> " & G34, F34 & G34) -> Failed - failed to aggregate - low entropy - domain knowledge v.s. Success** DID BETTER!!! BY CHANCE I GUESS.. | J34: Length Mismatch | K34: Mismatch - Lists lengths differ'
A35: Target1_62 | B35: Failed | C35: Success | D35: =VLOOKUP(Sheet1!A35,Sheet5!B$1:AA$613,26,FALSE) -> failed | E35: =VLOOKUP(Sheet1!A35,Sheet5!B$1:AA$613,25,FALSE) -> failed | F35: Success | G35: Success | H35: =C35 & " v.s. " & IF(AND(NOT(ISBLANK(F35)), NOT(ISBLANK(G35))), F35 & " --> " & G35, F35 & G35) -> Success v.s. Success --> Success | J35: Similarity Score Issue | K35: Scores: 0.9895, 1.0, 1.0; Case accuracy: 1.00 | L35: ['Column 1: Dec_2012 vs Dec_2013']
A36: Target1_65 | B36: Success | C36: Success | D36: =VLOOKUP(Sheet1!A36,Sheet5!B$1:AA$613,26,FALSE) -> 0 | E36: =VLOOKUP(Sheet1!A36,Sheet5!B$1:AA$613,25,FALSE) -> success | F36: Success | G36: Success | H36: =C36 & " v.s. " & IF(AND(NOT(ISBLANK(F36)), NOT(ISBLANK(G36))), F36 & " --> " & G36, F36 & G36) -> Success v.s. Success --> Success | J36: Success | K36: Execution successful without errors.
A37: Target1_67 | B37: Success | C37: Success | D37: =VLOOKUP(Sheet1!A37,Sheet5!B$1:AA$613,26,FALSE) -> #N/A | E37: =VLOOKUP(Sheet1!A37,Sheet5!B$1:AA$613,25,FALSE) -> #N/A | F37: Success | G37: Success | H37: =C37 & " v.s. " & IF(AND(NOT(ISBLANK(F37)), NOT(ISBLANK(G37))), F37 & " --> " & G37, F37 & G37) -> Success v.s. Success --> Success | J37: Success | K37: Execution successful without errors.
A38: Target1_68 | B38: Success | C38: Success | D38: =VLOOKUP(Sheet1!A38,Sheet5!B$1:AA$613,26,FALSE) -> #N/A | E38: =VLOOKUP(Sheet1!A38,Sheet5!B$1:AA$613,25,FALSE) -> #N/A | F38: Failed - DID NOT DO SUBSTRING | G38: Success | H38: =C38 & " v.s. " & IF(AND(NOT(ISBLANK(F38)), NOT(ISBLANK(G38))), F38 & " --> " & G38, F38 & G38) -> Success v.s. Failed - DID NOT DO SUBSTRING --> Success | I38: SQL is wrong: [(0, [(0, 'IGHV', 'IGHV1'), (1, 'IGHV', 'IGHV1') | J38: Success | K38: Execution successful without errors.
A39: Target1_71 | B39: Success | C39: Success | D39: =VLOOKUP(Sheet1!A39,Sheet5!B$1:AA$613,26,FALSE) -> success | E39: =VLOOKUP(Sheet1!A39,Sheet5!B$1:AA$613,25,FALSE) -> success | F39: Success | G39: Success | H39: =C39 & " v.s. " & IF(AND(NOT(ISBLANK(F39)), NOT(ISBLANK(G39))), F39 & " --> " & G39, F39 & G39) -> Success v.s. Success --> Success | J39: Success | K39: Execution successful without errors.
A40: Target1_72 | B40: Success | C40: Success | D40: =VLOOKUP(Sheet1!A40,Sheet5!B$1:AA$613,26,FALSE) -> failed | E40: =VLOOKUP(Sheet1!A40,Sheet5!B$1:AA$613,25,FALSE) -> failed | F40: Failed | G40: Failed | H40: =C40 & " v.s. " & IF(AND(NOT(ISBLANK(F40)), NOT(ISBLANK(G40))), F40 & " --> " & G40, F40 & G40) -> Success v.s. Failed --> Failed | I40: Error: ERROR: malformed array literal: "1" DETAIL: Array value must start with "{" or dimension information. CONTEXT: COPY Source1_72_0, line 2, column condition: "1" | J40: Success | K40: Execution successful without errors.
...

Sheet Sheet5
A1: Folder Name | B1: Target Data Name | C1: Target Data Schema | D1: Target Data Sample | E1: Target Data Description | F1: Source Data Name | G1: 3 Samples of Source Data | H1: Source Data Schema | I1: Failed SQL by GPT | J1: Failed Cases | K1: Ground Truth SQL | L1: Prompt_1(with csv) | M1: Prompt_2(with samples) | N1: sim score(with samples) | O1: PathsToSource1csv | P1: PathsToSource2csv | Q1: Comment(with samples) | R1: validation using s.csv and t.csv | S1: Final comments | T1: Accuracy Prompt 1 | U1: sim score in Prompt 1 | V1: error if any | W1: error in second run | X1: comment | Y1: React Result | Z1: Round 2 Accuracy Promp2 (with Target sample) | AA1: Round2 Accuracy Prompt1
A2: L1_0 | B2: Target1_0 | C2: ['State', 'AverageTemperature'] | D2: [['Acre', 25.76959388646288], ['Adygey', 10.203819706498953], ['Aga Buryat', -3.9832969187675102]] | E2: In target, the state wise average is computed from source. | F2: Source1_0 | G2: [['2002-11-01', 4.19, 0.187, 'Rostov', 'Russia'], ['1923-11-01', 26.761, 0.413, 'Sergipe', 'Brazil'], ['1994-09-01', 25.56, 0.245, 'Manipur', 'India']] | H2: ['dt', 'AverageTemperature', 'AverageTemperatureUncertainty', 'State', 'Country'] | L2: 0 | M2: 0 | T2: 0 | Y2: 1 | Z2: failed | AA2: failed, could not do aggregation
A3: L1_1 | B3: Target1_1 | C3: ['Student ID', 'student_name', 'gender', 'grade', 'school_name', 'reading_score', 'math_score', 'School ID', 'type', 'size', 'budget'] | D3: [[0, 'Paul Bradley', 'M', '9th', 'Huang High School', 66, 79, 0, 'District', 2917, 1910635], [1, 'Victor Smith', 'M', '12th', 'Huang High School', 94, 61, 0, 'District', 2917, 1910635], [2, 'Kevin Rodriguez', 'M', '12th', 'Huang High School', 90, 60, 0, 'District', 2917, 1910635]] | E3: Perform join on both source table and in case of ambiguity use school_name from source1_0 | F3: Source1_0 | G3: [[0, 'Paul Bradley', 'M', '9th', 'Huang High School', 66, 79], [1, 'Victor Smith', 'M', '12th', 'Huang High School', 94, 61], [2, 'Kevin Rodriguez', 'M', '12th', 'Huang High School', 90, 60]] | H3: ['Student ID', 'student_name', 'gender', 'grade', 'school_name', 'reading_score', 'math_score'] | K3: CREATE TABLE IF NOT EXISTS Source1_0 ( "Student ID" INT, student_name TEXT, gender CHAR(1), grade VARCHAR(10), school_name TEXT, reading_score INT, math_score INT ); -- Insert data into 'Source_0' INSERT INTO Source1_0 ("Student ID", student_name, gender, grade, school_name, reading_score, math_score) VALUES (0, 'Paul Bradley', 'M', '9th', 'Huang High School', 66, 79), (1, 'Victor Smith', 'M', '12th', 'Huang High School', 94, 61), (2, 'Kevin Rodriguez', 'M', '12th', 'Huang High School', 90, 60); -- Drop the second source table 'Source1_1' if it exists DROP TABLE IF EXISTS Source1_1; -- Create the second source table 'Source1_1' CREATE TABLE Source1_1 ( "School ID" INT, school_name TEXT, type TEXT, size INT, budget INT ); -- Insert data into 'Source1_1' INSERT INTO Source1_1 ("School ID", school_name, type, size, budget) VALUES (0, 'Huang High School', 'District', 2917, 1910635), (1, 'Figueroa High School', 'District', 2949, 1884411), (2, 'Shelton High School', 'Charter', 1761, 1056600); -- Create the target table 'target1' CREATE TABLE IF NOT EXISTS target1_1( "Student ID" INT, student_name TEXT, gender CHAR(1), grade VARCHAR(10), school_name TEXT, reading_score INT, math_score INT, "School ID" INT, type TEXT, size INT, budget INT ); -- Insert data into 'target1' by selecting only the necessary columns INSERT INTO target1_1 ( "Student ID", student_name, gender, grade, school_name, reading_score, math_score, "School ID", type, size, budget ) SELECT s0."Student ID", s0.student_name, s0.gender, s0.grade, s0.school_name, s0.reading_score, s0.math_score, s1."School ID", s1.type, s1.size, s1.budget FROM Source2_0 s0 JOIN Source2_1 s1 ON s0.school_name = s1.school_name; | L3: 0 | M3: 0.45 | R3: 0.45 | T3: 1 | AA3: success
F4: Source1_1 | G4: [[0, 'Huang High School', 'District', 2917, 1910635], [1, 'Figueroa High School', 'District', 2949, 1884411], [2, 'Shelton High School', 'Charter', 1761, 1056600]] | H4: ['School ID', 'school_name', 'type', 'size', 'budget']
A5: L1_10 | B5: Target1_10 | C5: ['PRECINCT', 'ELIGIBLE_VOTERS', 'POLLS', 'EARLY_VOING', 'ABSENTEE', 'PROVISIONAL'] | D5: [['001-000', 612, 408, 39, 19, 3], ['001-001', 27791, 13648, 5179, 1247, 462], ['001-002', 13695, 6576, 2601, 495, 307]] | E5: In target, the attributes are sum from source for each PRECINCT | F5: Source10_0 | G5: [['Allegany', 6.0, '01C', '001-000', 'DEMOCRAT', 83, 9, 4, 1, 126.0], ['Allegany', 6.0, '01C', '001-000', 'GREEN', 1, 0, 0, 1, 2.0], ['Allegany', 6.0, '01C', '001-000', 'LIBERTARIAN', 3, 0, 0, 0, 3.0]] | H5: ['LBE', 'CONGRESSIONAL_DISTRICT_CODE', 'LEGISLATIVE_DISTRICT_CODE', 'PRECINCT', 'PARTY', 'POLLS', 'EARLY_VOING', 'ABSENTEE', 'PROVISIONAL', 'ELIGIBLE_VOTERS'] | L5: 0 | M5: 0 | R5: 0 | T5: 0 | Z5: succes | AA5: failed
A6: L1_11 | B6: Target1_11 | C6: ['sex', 'births'] | D6: [['F', 90993], ['M', 80202]] | E6: In target table births is sum of births from source table. sex is group by as 'M' and 'F' and order by sex. | F6: Source11_0 | G6: [['Mary', 'F', 7065], ['Anna', 'F', 2604], ['Emma', 'F', 2003]] | H6: ['name', 'sex', 'births'] | L6: 0 | M6: 0 | R6: 1 | S6: data type mismatch to be resolved. Done | T6: 0 | Y6: 1 | Z6: failed | AA6: failed
A7: L1_12 | B7: Target1_12 | C7: ['Athlete', 'Age', 'Year', 'Closing Ceremony Date', 'Gold Medals', 'Silver Medals', 'Bronze Medals', 'Total Medals', 'Country'] | D7: [['Michael Phelps', 23.0, 2008, '08/24/2008', 8, 0, 0, 8, 'United States'], ['Michael Phelps', 19.0, 2004, '08/29/2004', 6, 0, 2, 8, 'United States'], ['Michael Phelps', 27.0, 2012, '08/12/2012', 4, 2, 0, 6, 'United States']] | E7: Use join on source tables. | F7: Source12_0 | G7: [['Michael Phelps', 23.0, 2008, '08/24/2008', 8, 0, 0, 8], ['Michael Phelps', 19.0, 2004, '08/29/2004', 6, 0, 2, 8], ['Michael Phelps', 27.0, 2012, '08/12/2012', 4, 2, 0, 6]] | H7: ['Athlete', 'Age', 'Year', 'Closing Ceremony Date', 'Gold Medals', 'Silver Medals', 'Bronze Medals', 'Total Medals'] | M7: 0 | R7: 0 | T7: 0
F8: Source12_1 | G8: [['Michael Phelps', 'United States'], ['Natalie Coughlin', 'United States'], ['Aleksey Nemov', 'Russia']] | H8: ['Athlete', 'Country'] | L8: 0 | M8: 0
A9: L1_13 | B9: Target1_13 | C9: ['sex', 'smoker', 'tip_pct'] | D9: [['Female', 'No', 0.15441878619164726], ['Female', 'Yes', 0.19843132079721], ['Male', 'No', 0.16243793099990006]] | E9: In target, for sex and smoker the tip_pct is averaged from source. | F9: Source13_0 | G9: [[16.99, 1.01, 'Female', 'No', 'Sun', 'Dinner', 2, 0.059446733372572114], [10.34, 1.66, 'Male', 'No', 'Sun', 'Dinner', 3, 0.16054158607350094], [21.01, 3.5, 'Male', 'No', 'Sun', 'Dinner', 3, 0.16658733936220846]] | H9: ['total_bill', 'tip', 'sex', 'smoker', 'day', 'time', 'size', 'tip_pct'] | L9: 0 | M9: 0 | R9: 0 | T9: 0 | Y9: fail | Z9: failed | AA9: failed
A10: L1_14 | B10: Target1_14 | C10: ['PLAYER', '2017-18', '#', 'Player', 'Team', 'GP', 'MPG', 'FGM', 'FGA', 'FG%', '3PM', '3PA', '3P%', 'FTM', 'FTA', 'FT%', 'TOV', 'PF', 'ORB', 'DRB', 'RPG', 'APG', 'SPG', 'BPG', 'PPG'] | D10: [['Stephen Curry', 34682550, 1, 'Stephen Curry', 'GSW', 51, 32.0, 8.4, 16.9, 0.495, 4.2, 9.8, 0.423, 5.5, 5.9, 0.921, 3.0, 2.2, 0.7, 4.4, 5.1, 6.1, 1.6, 0.2, 26.4], ['Kevin Durant', 25000000, 2, 'Kevin Durant', 'GSW', 68, 34.2, 9.3, 18.0, 0.516, 2.5, 6.1, 0.419, 5.3, 5.9, 0.889, 3.0, 2.0, 0.5, 6.4, 6.8, 5.4, 0.7, 1.8, 26.4], ['Klay Thompson', 17826150, 3, 'Klay Thompson', 'GSW', 73, 34.3, 7.9, 16.1, 0.488, 3.1, 7.1, 0.44, 1.1, 1.3, 0.8370000000000001, 1.8, 1.6, 0.4, 3.4, 3.8, 2.5, 0.8, 0.5, 20.0]] | E10: In target, join is done on source tables. | F10: Source14_0 | G10: [['Stephen Curry', 34682550], ['Kevin Durant', 25000000], ['Klay Thompson', 17826150]] | H10: ['PLAYER', '2017-18'] | I10: DROP TABLE IF EXISTS Source14_0; CREATE TABLE Source14_0 ( "PLAYER" VARCHAR(255), "2017-18" NUMERIC ); -- Insert data into the first table Source14_0 COPY Source14_0 ("PLAYER", "2017-18") FROM 'D:\lab\ChatGPTwithSQLscript\github-pipelines\length1_14\test_0.csv' DELIMITER ',' CSV HEADER NULL 'nan'; -- Create the second table Source14_1 DROP TABLE IF EXISTS Source14_1; CREATE TABLE Source14_1 ( "#" INTEGER, "Player" VARCHAR(255), "Team" VARCHAR(255), "GP" INTEGER, "MPG" NUMERIC, "FGM" NUMERIC, "FGA" NUMERIC, "FG%" NUMERIC, "3PM" NUMERIC, "3PA" NUMERIC, "3P%" NUMERIC, "FTM" NUMERIC, "FTA" NUMERIC, "FT%" NUMERIC, "TOV" NUMERIC, "PF" NUMERIC, "ORB" NUMERIC, "DRB" NUMERIC, "RPG" NUMERIC, "APG" NUMERIC, "SPG" NUMERIC, "BPG" NUMERIC, "PPG" NUMERIC ); -- Insert data into the second table Source14_1 COPY Source14_1 ("#", "Player", "Team", "GP", "MPG", "FGM", "FGA", "FG%", "3PM", "3PA", "3P%", "FTM", "FTA", "FT%", "TOV", "PF", "ORB", "DRB", "RPG", "APG", "SPG", "BPG", "PPG") FROM 'D:\lab\ChatGPTwithSQLscript\github-pipelines\length1_14\test_1.csv' DELIMITER ',' CSV HEADER NULL 'nan'; -- Create the target table Target1_14 DROP TABLE IF EXISTS Target1_14; CREATE TABLE Target1_14 AS SELECT "PLAYER", "2017-18", "#", "Player", "Team", "GP", "MPG", "FGM", "FGA", "FG%", "3PM", "3PA", "3P%", "FTM", "FTA", "FT%", "TOV", "PF", "ORB", "DRB", "RPG", "APG", "SPG", "BPG", "PPG" FROM Source14_0 JOIN Source14_1 ON Source14_0."PLAYER" = Source14_1."Player"; -- Export the result to a CSV file COPY Target1_14 TO 'D:\lab\ChatGPTwithSQLscript\github-pipelines\length1_14\Target1_14_result.csv' DELIMITER ',' CSV HEADER; | J10: SQL Result: Table name not identified from last INSERT INTO query. | L10: 0 | M10: 1 | N10: [1.0, 1.0, 1.0, 1.0, 1.0, 1.0, 1.0, 1.0, 1.0, 1.0, 1.0, 1.0, 1.0, 1.0, 1.0, 1.0, 1.0, 1.0, 1.0, 1.0, 1.0, 1.0, 1.0, 1.0, 1.0] | Q10: second time running the script gives correct result., no chnages were made. | R10: 0.84 | T10: Fail | V10: ERROR: column "player" specified more than once
F11: Source14_1 | G11: [[1, 'Stephen Curry', 'GSW', 51, 32.0, 8.4, 16.9, 0.495, 4.2, 9.8, 0.423, 5.5, 5.9, 0.921, 3.0, 2.2, 0.7, 4.4, 5.1, 6.1, 1.6, 0.2, 26.4], [2, 'Kevin Durant', 'GSW', 68, 34.2, 9.3, 18.0, 0.516, 2.5, 6.1, 0.419, 5.3, 5.9, 0.889, 3.0, 2.0, 0.5, 6.4, 6.8, 5.4, 0.7, 1.8, 26.4], [3, 'Klay Thompson', 'GSW', 73, 34.3, 7.9, 16.1, 0.488, 3.1, 7.1, 0.44, 1.1, 1.3, 0.8370000000000001, 1.8, 1.6, 0.4, 3.4, 3.8, 2.5, 0.8, 0.5, 20.0]] | H11: ['#', 'Player', 'Team', 'GP', 'MPG', 'FGM', 'FGA', 'FG%', '3PM', '3PA', '3P%', 'FTM', 'FTA', 'FT%', 'TOV', 'PF', 'ORB', 'DRB', 'RPG', 'APG', 'SPG', 'BPG', 'PPG'] | J11: On executing this queri in postgres, gives correct result.,
A12: L1_15 | B12: Target1_15 | C12: ['State', 'Participation_x', 'English', 'Math_x', 'Reading', 'Science', 'Composite', 'Participation_y', 'Evidence-Based Reading and Writing', 'Math_y', 'Total'] | D12: [['Alabama', '100%', 18.9, 18.4, 19.7, 19.4, 19.2, '5%', 593, 572, 1165], ['Alaska', '65%', 18.7, 19.8, 20.4, 19.9, 19.8, '38%', 547, 533, 1080], ['Arizona', '62%', 18.6, 19.8, 20.1, 19.8, 19.7, '30%', 563, 553, 1116]] | E12: Participation is percentage value and join is performed | F12: Source15_0 | G12: [['National', ' 60%', 20.3, 20.7, 21.4, 21.0, 21.0], ['Alabama', '100%', 18.9, 18.4, 19.7, 19.4, 19.2], ['Alaska', '65%', 18.7, 19.8, 20.4, 19.9, 19.8]] | H12: ['State', 'Participation', 'English', 'Math', 'Reading', 'Science', 'Composite'] | M12: 1 | N12: [1.0, 1.0, 1.0, 1.0, 1.0, 1.0, 1.0, 1.0, 1.0, 1.0, 1.0] | R12: 0.27 | T12: 0 | X12: The result and sql seems correct, but still match failed. Can check later why failed
F13: Source15_1 | G13: [['Alabama', '5%', 593, 572, 1165], ['Alaska', '38%', 547, 533, 1080], ['Arizona', '30%', 563, 553, 1116]] | H13: ['State', 'Participation', 'Evidence-Based Reading and Writing', 'Math', 'Total']
A14: L1_16 | B14: Target1_16 | C14: ['CUSTOMERNAME', 'ORDERNUMBER'] | D14: [['Alpha Cognac', 7], ['Amica Models & Co.', 19], ['Auto-Moto Classics Inc.', 3]] | E14: In target, the ordernumber is count for each customername from source table. | F14: Source16_0 | G14: [[10107, 30.0, 95.7, 2.0, 2871.0, '2/24/2003 0:00', 'Shipped', 1.0, 2.0, 2003.0, 'Motorcycles', 95.0, 'S10_1678', 'Land of Toys Inc.', '2125557818', '897 Long Airport Avenue', nan, 'NYC', 'NY', 10022, 'USA', nan, 'Yu', 'Kwai', 'Small'], [10121, 34.0, 81.35, 5.0, 2765.9, '5/7/2003 0:00', 'Shipped', 2.0, 5.0, 2003.0, 'Motorcycles', 95.0, 'S10_1678', 'Reims Collectables', '26.47.1555', "59 rue de l'Abbaye", nan, 'Reims', nan, 51100, 'France', 'EMEA', 'Henriot', 'Paul', 'Small'], [10134, 41.0, 94.74, 2.0, 3884.34, '7/1/2003 0:00', 'Shipped', 3.0, 7.0, 2003.0, 'Motorcycles', 95.0, 'S10_1678', 'Lyon Souveniers', '+33 1 46 62 7555', '27 rue du Colonel Pierre Avia', nan, 'Paris', nan, 75508, 'France', 'EMEA', 'Da Cunha', 'Daniel', 'Medium']] | H14: ['ORDERNUMBER', 'QUANTITYORDERED', 'PRICEEACH', 'ORDERLINENUMBER', 'SALES', 'ORDERDATE', 'STATUS', 'QTR_ID', 'MONTH_ID', 'YEAR_ID', 'PRODUCTLINE', 'MSRP', 'PRODUCTCODE', 'CUSTOMERNAME', 'PHONE', 'ADDRESSLINE1', 'ADDRESSLINE2', 'CITY', 'STATE', 'POSTALCODE', 'COUNTRY', 'TERRITORY', 'CONTACTLASTNAME', 'CONTACTFIRSTNAME', 'DEALSIZE'] | L14: 0 | T14: Fail | V14: Error: ERROR: invalid input syntax for type integer: "10180,29,86.13,9,2497.77,11/11/2003 0:00,Shipped,4,11,2003,Motorcycles,95,S10_1678,Daedalus Designs Imports,20.16.1555,"184, chausse de Tournai",,Lille,,59000,France,EMEA,Rance,Martine,Small" CONTEXT: COPY source16_0, line 8, column ordernumber: "10180,29,86.13,9,2497.77,11/11/2003 0:00,Shipped,4,11,2003,Motorcycles,95,S10_1678,Daedalus Designs ..." | W14: Error: ERROR: invalid input syntax for type integer: "" | Z14: Still failed even after clean.py pre processing | AA14: failed
A15: L1_17 | B15: Target1_17 | C15: ['School ID', 'school_name', 'type', 'size', 'budget', 'Student ID', 'student_name', 'gender', 'grade', 'reading_score', 'math_score'] | D15: [[0, 'Huang High School', 'District', 2917, 1910635, 0, 'Paul Bradley', 'M', '9th', 66, 79], [0, 'Huang High School', 'District', 2917, 1910635, 1, 'Victor Smith', 'M', '12th', 94, 61], [0, 'Huang High School', 'District', 2917, 1910635, 2, 'Kevin Rodriguez', 'M', '12th', 90, 60]] | E15: Join is perfomed from source table. | F15: Source17_0 | G15: [[0, 'Huang High School', 'District', 2917, 1910635], [1, 'Figueroa High School', 'District', 2949, 1884411], [2, 'Shelton High School', 'Charter', 1761, 1056600]] | H15: ['School ID', 'school_name', 'type', 'size', 'budget'] | M15: 0.45 | N15: 0.9996936430942047, 1.0, 1.0, 0.9996936430942047, 0.9996936430942047, 0.6655603778401838, 1.0, 1.0, 1.0, 0.6762318100587184, 0.6737809548123564 | T15: 1 | AA15: success
F16: Source17_1 | G16: [[0, 'Paul Bradley', 'M', '9th', 'Huang High School', 66, 79], [1, 'Victor Smith', 'M', '12th', 'Huang High School', 94, 61], [2, 'Kevin Rodriguez', 'M', '12th', 'Huang High School', 90, 60]] | H16: ['Student ID', 'student_name', 'gender', 'grade', 'school_name', 'reading_score', 'math_score']
A17: L1_18 | B17: Target1_18 | C17: ['y', 'sepal length (cm)', 'sepal width (cm)', 'petal length (cm)', 'petal width (cm)'] | D17: [[0, 50, 50, 50, 50], [1, 25, 25, 25, 25]] | E17: In target, for each y, the count of attribute is calculated from source tables. | F17: Source18_0 | G17: [[5.1, 3.5, 1.4, 0.2, 0.0], [4.9, 3.0, 1.4, 0.2, 0.0], [4.7, 3.2, 1.3, 0.2, 0.0]] | H17: ['sepal length (cm)', 'sepal width (cm)', 'petal length (cm)', 'petal width (cm)', 'y'] | L17: 0 | T17: 0 | Z17: failed | AA17: failed
A18: L1_19 | B18: Target1_19 | C18: ['ocd_prop_id', 'calaccess_prop_id', 'ccdc_prop_id', 'prop_name', 'ccdc_committee_id', 'calaccess_committee_id', 'committee_name_x', 'committee_position', 'committee_name_y', 'calaccess_filing_id', 'date_received', 'contributor_lastname', 'contributor_firstname', 'contributor_city', 'contributor_state', 'contributor_zip', 'contributor_employer', 'contributor_occupation', 'contributor_is_self_employed', 'amount'] | D18: [['ocd-contest/e0c5f9f0-63a9-4c15-9a5c-017e20ac15bc', 1381642, 73, 'PROPOSITION 054 - LEGISLATURE. LEGISLATION AND PROCEEDINGS. INITIATIVE CONSTITUTIONAL AMENDMENT AND STATUTE.', 396, 1389997, 'CALIFORNIA COMMON CAUSE -- YES ON 54 AND 59 (NONPROFIT 501(C)(4)', 'SUPPORT', 'CALIFORNIA COMMON CAUSE -- YES ON 54 AND 59 (NONPROFIT 501(C)(4)', 2098058, '2016-07-01', 'KORMUNDOY', 'EDWARD', 'LOS ANGELES', 'CA', 90026, 'RETIRED', 'RETIRED', False, 100.0], ['ocd-contest/e0c5f9f0-63a9-4c15-9a5c-017e20ac15bc', 1381642, 73, 'PROPOSITION 054 - LEGISLATURE. LEGISLATION AND PROCEEDINGS. INITIATIVE CONSTITUTIONAL AMENDMENT AND STATUTE.', 396, 1389997, 'CALIFORNIA COMMON CAUSE -- YES ON 54 AND 59 (NONPROFIT 501(C)(4)', 'SUPPORT', 'CALIFORNIA COMMON CAUSE -- YES ON 54 AND 59 (NONPROFIT 501(C)(4)', 2098058, '2016-07-03', 'CARSON', 'RICHARD', 'NEVADA CITY', 'CA', 95959, 'RETIRED', 'RETIRED', False, 100.0], ['ocd-contest/e0c5f9f0-63a9-4c15-9a5c-017e20ac15bc', 1381642, 73, 'PROPOSITION 054 - LEGISLATURE. LEGISLATION AND PROCEEDINGS. INITIATIVE CONSTITUTIONAL AMENDMENT AND STATUTE.', 396, 1389997, 'CALIFORNIA COMMON CAUSE -- YES ON 54 AND 59 (NONPROFIT 501(C)(4)', 'SUPPORT', 'CALIFORNIA COMMON CAUSE -- YES ON 54 AND 59 (NONPROFIT 501(C)(4)', 2098058, '2016-09-20', 'MORRISON', 'JAMES', 'HUNTINGTON BEACH', 'CA', 92647, 'RETIRED', 'RETIRED', False, 59.0]] | E18: contributor_zip type should be string in the tables | F18: Source19_0 | G18: [['ocd-contest/b51dc64d-3562-4913-a190-69f5088c22a6', 1376258, 70, 'PROPOSITION 051 - SCHOOL BONDS. FUNDING FOR K-12 SCHOOL AND COMMUNITY COLLEGE FACILITIES. INITIATIVE STATUTORY AMENDMENT.', 382, 1374469, 'YES ON PROPOSITION 51 - CALIFORNIANS FOR QUALITY SCHOOLS, SPONSORED AND FUNDED BY COALITION FOR ADEQUATE SCHOOL HOUSING ISSUES COMMITTEE AND CALIFORNIA BUILDING INDUSTRY ASSOCIATION ISSUES COMMITTEE', 'SUPPORT'], ['ocd-contest/b51dc64d-3562-4913-a190-69f5088c22a6', 1376258, 70, 'PROPOSITION 051 - SCHOOL BONDS. FUNDING FOR K-12 SCHOOL AND COMMUNITY COLLEGE FACILITIES. INITIATIVE STATUTORY AMENDMENT.', 383, 1220380, 'COMMUNITY COLLEGE FACILITY COALITION ISSUES COMMITTEE, YES ON 51', 'SUPPORT'], ['ocd-contest/b51dc64d-3562-4913-a190-69f5088c22a6', 1376258, 70, 'PROPOSITION 051 - SCHOOL BONDS. FUNDING FOR K-12 SCHOOL AND COMMUNITY COLLEGE FACILITIES. INITIATIVE STATUTORY AMENDMENT.', 384, 1282321, "TORLAKSON'S INVEST IN CALIFORNIA A BALLOT MEASURE COMMITTEE TO SUPPORT PROPOSITION 51, SUPERINTENDENT TOM", 'SUPPORT']] | H18: ['ocd_prop_id', 'calaccess_prop_id', 'ccdc_prop_id', 'prop_name', 'ccdc_committee_id', 'calaccess_committee_id', 'committee_name', 'committee_position'] | I18: CREATE TABLE IF NOT EXISTS Source19_0 ( ocd_prop_id TEXT, calaccess_prop_id INTEGER, ccdc_prop_id INTEGER, prop_name TEXT, ccdc_committee_id INTEGER, calaccess_committee_id INTEGER, committee_name TEXT, committee_position TEXT ); CREATE TABLE IF NOT EXISTS Source19_1 ( calaccess_committee_id INTEGER, committee_name TEXT, calaccess_filing_id INTEGER, date_received DATE, contributor_lastname TEXT, contributor_firstname TEXT, contributor_city TEXT, contributor_state TEXT, contributor_zip INTEGER, contributor_employer TEXT, contributor_occupation TEXT, contributor_is_self_employed BOOLEAN, amount FLOAT ); -- Step 2: Insert data into the source tables from CSV files COPY Source19_0 FROM 'D:\lab\ChatGPTwithSQLscript\github-pipelines\length1_19\test_0.csv' DELIMITER ',' CSV HEADER NULL ''; COPY Source19_1 FROM 'D:\lab\ChatGPTwithSQLscript\github-pipelines\length1_19\test_1.csv' DELIMITER ',' CSV HEADER NULL ''; -- Step 3: Create the target table CREATE TABLE IF NOT EXISTS Target1_19 ( ocd_prop_id TEXT, calaccess_prop_id INTEGER, ccdc_prop_id INTEGER, prop_name TEXT, ccdc_committee_id INTEGER, calaccess_committee_id INTEGER, committee_name_x TEXT, committee_position TEXT, committee_name_y TEXT, calaccess_filing_id INTEGER, date_received DATE, contributor_lastname TEXT, contributor_firstname TEXT, contributor_city TEXT, contributor_state TEXT, contributor_zip INTEGER, contributor_employer TEXT, contributor_occupation TEXT, contributor_is_self_employed BOOLEAN, amount FLOAT ); -- Step 4: Insert data into the target table by joining the source tables INSERT INTO Target1_19 ( ocd_prop_id, calaccess_prop_id, ccdc_prop_id, prop_name, ccdc_committee_id, calaccess_committee_id, committee_name_x, committee_position, committee_name_y, calaccess_filing_id, date_received, contributor_lastname, contributor_firstname, contributor_city, contributor_state, contributor_zip, contributor_employer, contributor_occupation, contributor_is_self_employed, amount ) SELECT s0.ocd_prop_id, s0.calaccess_prop_id, s0.ccdc_prop_id, s0.prop_name, s0.ccdc_committee_id, s0.calaccess_committee_id, s0.committee_name, s0.committee_position, s1.committee_name, s1.calaccess_filing_id, s1.date_received, s1.contributor_lastname, s1.contributor_firstname, s1.contributor_city, s1.contributor_state, s1.contributor_zip, s1.contributor_employer, s1.contributor_occupation, s1.contributor_is_self_employed, s1.amount FROM Source19_0 s0 JOIN Source19_1 s1 ON s0.calaccess_committee_id = s1.calaccess_committee_id; -- Step 5: Export the result to a CSV file COPY (SELECT * FROM Target1_19) TO 'D:\lab\ChatGPTwithSQLscript\github-pipelines\length1_19\Target1_19_result.csv' DELIMITER ',' CSV HEADER; | J18: ERROR: invalid input syntax for type integer: "20036-5610" CONTEXT: COPY source19_1, line 56, column contributor_zip: "20036-5610" | T18: 0.95 | U18: 1.0, 1.0, 1.0, 1.0, 1.0, 1.0, 1.0, 1.0, 1.0, 1.0, 1.0, 1.0, 1.0, 1.0, 1.0, 1.0, 1.0, 1.0, 0.0, 1.0 | X18: The csv file cont to compare is same but still last second column shows 0 matching. Check later.
F19: Source19_1 | G19: [[1386560, 'ADULT USE CAMPAIGN FOR PROPOSITION 64; THE', 2083796, '2016-09-18', 'BERGMAN', 'GRETCHEN', 'SPRING VALLEY', 'CA', 91978, 'A NEW PATH', 'EXECUTIVE DIRECTOR', False, 84.0], [1386560, 'ADULT USE CAMPAIGN FOR PROPOSITION 64; THE', 2083796, '2016-09-18', 'KAHLE', 'MYRNA', 'SAN DIEGO', 'CA', 92109, 'NATIONAL SCHOOL DISTRICT', 'TEACHER', False, 35.0], [1386560, 'ADULT USE CAMPAIGN FOR PROPOSITION 64; THE', 2083796, '2016-07-15', 'MCDEVITT', 'LEO', 'ESCONDIDO', 'CA', 92025, 'LIFE IONIZERS', 'SEO/CONTENT MANAGER', False, 198.0]] | H19: ['calaccess_committee_id', 'committee_name', 'calaccess_filing_id', 'date_received', 'contributor_lastname', 'contributor_firstname', 'contributor_city', 'contributor_state', 'contributor_zip', 'contributor_employer', 'contributor_occupation', 'contributor_is_self_employed', 'amount'] | L19: 0
A20: L1_2 | B20: Target1_2 | C20: ['tripduration', 'starttime', 'stoptime', 'start station id', 'start station name', 'start station latitude', 'start station longitude', 'end station id', 'end station name', 'end station latitude', 'end station longitude', 'bikeid', 'usertype', 'birth year', 'gender'] | D20: [[131, '2018-05-01 07:29:57.5490', '2018-05-01 07:32:08.6160', 3183, 'Exchange Place', 40.7162469, -74.0334588, 3184, 'Paulus Hook', 40.7141454, -74.0335519, 29617, 'Subscriber', 1966, 1], [73, '2018-05-01 08:13:58.2560', '2018-05-01 08:15:11.9230', 3183, 'Exchange Place', 40.7162469, -74.0334588, 3184, 'Paulus Hook', 40.7141454, -74.0335519, 29288, 'Subscriber', 1975, 1], [4929, '2018-05-01 08:17:21.3110', '2018-05-01 09:39:31.0770', 3183, 'Exchange Place', 40.7162469, -74.0334588, 3183, 'Exchange Place', 40.7162469, -74.0334588, 29520, 'Customer', 1969, 0]] | F20: Source2_0 | G20: [[329, '2018-06-01 07:07:00.2990', '2018-06-01 07:12:30.2220', 3183, 'Exchange Place', 40.7162469, -74.0334588, 3276, 'Marin Light Rail', 40.71458403535893, -74.04281705617905, 29513, 'Subscriber', 1991, 1], [259, '2018-06-01 08:24:43.8490', '2018-06-01 08:29:03.8450', 3183, 'Exchange Place', 40.7162469, -74.0334588, 3267, 'Morris Canal', 40.7124188237569, -74.03852552175522, 26221, 'Subscriber', 1989, 2], [686, '2018-06-01 09:17:49.5730', '2018-06-01 09:29:16.1770', 3183, 'Exchange Place', 40.7162469, -74.0334588, 3202, 'Newport PATH', 40.7272235, -74.03375890000002, 29266, 'Subscriber', 1990, 1]] | H20: ['tripduration', 'starttime', 'stoptime', 'start station id', 'start station name', 'start station latitude', 'start station longitude', 'end station id', 'end station name', 'end station latitude', 'end station longitude', 'bikeid', 'usertype', 'birth year', 'gender'] | K20: DROP TABLE IF EXISTS Source2_0; CREATE TABLE Source2_0 ( tripduration INTEGER, starttime TIMESTAMP, stoptime TIMESTAMP, "start station id" INTEGER, "start station name" VARCHAR(255), "start station latitude" FLOAT, "start station longitude" FLOAT, "end station id" INTEGER, "end station name" VARCHAR(255), "end station latitude" FLOAT, "end station longitude" FLOAT, bikeid INTEGER, usertype VARCHAR(255), "birth year" INTEGER, gender INTEGER ); DROP TABLE IF EXISTS Source2_1; CREATE TABLE Source2_1 ( tripduration INTEGER, starttime TIMESTAMP, stoptime TIMESTAMP, "start station id" INTEGER, "start station name" VARCHAR(255), "start station latitude" FLOAT, "start station longitude" FLOAT, "end station id" INTEGER, "end station name" VARCHAR(255), "end station latitude" FLOAT, "end station longitude" FLOAT, bikeid INTEGER, usertype VARCHAR(255), "birth year" INTEGER, gender INTEGER ); -- Step 2: Insert data from CSV files into the source tables COPY Source2_0 FROM 'D:\lab\ChatGPTwithSQLscript\github-pipelines\length1_2\test_0.csv' DELIMITER ',' CSV HEADER NULL ''; COPY Source2_1 FROM 'D:\lab\ChatGPTwithSQLscript\github-pipelines\length1_2\test_1.csv' DELIMITER ',' CSV HEADER NULL ''; -- Step 3: Create the target table DROP TABLE IF EXISTS Target1_2; CREATE TABLE Target1_2 ( tripduration INTEGER, starttime TIMESTAMP, stoptime TIMESTAMP, "start station id" INTEGER, "start station name" VARCHAR(255), "start station latitude" FLOAT, "start station longitude" FLOAT, "end station id" INTEGER, "end station name" VARCHAR(255), "end station latitude" FLOAT, "end station longitude" FLOAT, bikeid INTEGER, usertype VARCHAR(255), "birth year" INTEGER, gender INTEGER ); -- Step 4: Insert data from source tables into the target table INSERT INTO Target1_2 ( tripduration, starttime, stoptime, "start station id", "start station name", "start station latitude", "start station longitude", "end station id", "end station name", "end station latitude", "end station longitude", bikeid, usertype, "birth year", gender ) SELECT tripduration, starttime, stoptime, "start station id", "start station name", "start station latitude", "start station longitude", "end station id", "end station name", "end station latitude", "end station longitude", bikeid, usertype, "birth year", gender FROM Source2_0 UNION ALL SELECT tripduration, starttime, stoptime, "start station id", "start station name", "start station latitude", "start station longitude", "end station id", "end station name", "end station latitude", "end station longitude", bikeid, usertype, "birth year", gender FROM Source2_1; -- Step 5: Export the result to a CSV file COPY ( SELECT * FROM Target1_2 ) TO 'D:\lab\ChatGPTwithSQLscript\github-pipelines\length1_2\Target1_2_result.csv' DELIMITER ',' CSV HEADER; | M20: 0.2 | N20: [0.0013109023377758358, 0.0, 0.0, 0.09558662879615469, 1.0, 0.09558662879615469, 0.09558662879615469, 0.04040128177117471, 1.0, 0.04040128177117471, 0.04040128177117471, 0.0019117325759230937, 1.0, 0.035813123588959286, 0.5586264656616415] | Q20: The gpt generate results seems correct but due to ordering the accuracy is so low. Can not figure out the ordering. | T20: 0.87 | U20: 1.0, 0.0, 0.0, 1.0, 1.0, 1.0, 1.0, 1.0, 1.0, 1.0, 1.0, 1.0, 1.0, 1.0, 1.0 | W20: 1.0, 0.0, 0.0, 1.0, 1.0, 1.0, 1.0, 1.0, 1.0, 1.0, 1.0, 1.0, 1.0, 1.0, 1.0 | X20: The sim score is different
F21: Source2_1 | G21: [[131, '2018-05-01 07:29:57.5490', '2018-05-01 07:32:08.6160', 3183, 'Exchange Place', 40.7162469, -74.0334588, 3184, 'Paulus Hook', 40.7141454, -74.0335519, 29617, 'Subscriber', 1966, 1], [73, '2018-05-01 08:13:58.2560', '2018-05-01 08:15:11.9230', 3183, 'Exchange Place', 40.7162469, -74.0334588, 3184, 'Paulus Hook', 40.7141454, -74.0335519, 29288, 'Subscriber', 1975, 1], [4929, '2018-05-01 08:17:21.3110', '2018-05-01 09:39:31.0770', 3183, 'Exchange Place', 40.7162469, -74.0334588, 3183, 'Exchange Place', 40.7162469, -74.0334588, 29520, 'Customer', 1969, 0]] | H21: ['tripduration', 'starttime', 'stoptime', 'start station id', 'start station name', 'start station latitude', 'start station longitude', 'end station id', 'end station name', 'end station latitude', 'end station longitude', 'bikeid', 'usertype', 'birth year', 'gender'] | L21: 0 | X21: After checking both files, ordering
A22: L1_20 | B22: Target1_20 | C22: ['sex', 'smoker', 'total_bill', 'tip', 'size'] | D22: [['Female', 'No', 18.846206896551728, 2.8279310344827597, 2.5172413793103448], ['Female', 'Yes', 18.504, 2.992, 2.0], ['Male', 'No', 19.666615384615387, 3.1616923076923067, 2.569230769230769]] | F22: Source20_0 | G22: [[16.99, 1.01, 'Female', 'No', 'Sun', 'Dinner', 2], [10.34, 1.66, 'Male', 'No', 'Sun', 'Dinner', 3], [21.01, 3.5, 'Male', 'No', 'Sun', 'Dinner', 3]] | H22: ['total_bill', 'tip', 'sex', 'smoker', 'day', 'time', 'size'] | L22: 0 | T22: 0 | Z22: failed | AA22: failed
A23: L1_21 | B23: Target1_21 | C23: ['Major_category', 'Median'] | D23: [['Agriculture & Natural Resources', 55000.0], ['Biology & Life Science', 51833.33333333334], ['Communications & Journalism', 49500.0]] | E23: In target, for Major_category and Median type the , Median are averaged from source table | F23: Source21_0 | G23: [[1100, 'GENERAL AGRICULTURE', 'Agriculture & Natural Resources', 128148, 90245, 74078, 2423, 0.026147106, 50000, 34000, 80000], [1101, 'AGRICULTURE PRODUCTION AND MANAGEMENT', 'Agriculture & Natural Resources', 95326, 76865, 64240, 2266, 0.028636059, 54000, 36000, 80000], [1102, 'AGRICULTURAL ECONOMICS', 'Agriculture & Natural Resources', 33955, 26321, 22810, 821, 0.030248324, 63000, 40000, 98000]] | H23: ['Major_code', 'Major', 'Major_category', 'Total', 'Employed', 'Employed_full_time_year_round', 'Unemployed', 'Unemployment_rate', 'Median', 'P25th', 'P75th'] | K23: DROP TABLE IF EXISTS Source21_0; CREATE TABLE Source21_0 ( Major_code INT, Major VARCHAR(255), Major_category VARCHAR(255), Total INT, Employed INT, Employed_full_time_year_round INT, Unemployed INT, Unemployment_rate FLOAT, Median INT, P25th INT, P75th INT ); -- Insert sample rows into the source table INSERT INTO Source21_0 (Major_code, Major, Major_category, Total, Employed, Employed_full_time_year_round, Unemployed, Unemployment_rate, Median, P25th, P75th) VALUES (1100, 'GENERAL AGRICULTURE', 'Agriculture & Natural Resources', 128148, 90245, 74078, 2423, 0.026147106, 50000, 34000, 80000), (1101, 'AGRICULTURE PRODUCTION AND MANAGEMENT', 'Agriculture & Natural Resources', 95326, 76865, 64240, 2266, 0.028636059, 54000, 36000, 80000), (1102, 'AGRICULTURAL ECONOMICS', 'Agriculture & Natural Resources', 33955, 26321, 22810, 821, 0.030248324, 63000, 40000, 98000); -- Create the target table DROP TABLE IF EXISTS Target1_21; CREATE TABLE Target1_21 ( Major_category VARCHAR(255), Median FLOAT ); -- Insert rows from the source table into the target table INSERT INTO Target1_21 (Major_category, Median) SELECT Major_category, AVG(Median) AS Median FROM Source21_0 GROUP BY Major_category; -- Export the result to a CSV file SELECT * FROM Target1_21; | M23: 0 | Q23: The SQL result is correct but comparision acc is 0 | R23: CSV file upload have more columns | T23: 0 | Z23: success | AA23: failed
A24: L1_22 | B24: Target1_22 | C24: ['condition', 'click'] | D24: [[0, 253], [1, 246]] | F24: Source22_0 | G24: [[1, 0], [0, 0], [0, 0]] | H24: ['condition', 'click'] | L24: 0 | T24: 0 | Z24: failed | AA24: failed
A25: L1_23 | B25: Target1_23 | C25: ['customer_id', 'amount'] | D25: [[80.0, 75.0], [90.0, 121.33333333333331], [130.0, 60.0]] | F25: Source23_0 | G25: [[760, 25, '2009-11-06'], [860, 50, '2012-09-28'], [1200, 100, '2005-10-25']] | H25: ['customer_id', 'amount', 'date'] | L25: 0 | T25: 0 | Z25: failed | AA25: failed
